<?xml version="1.0" ?>
<sdf version='1.6'>
  <model name='4DOFManipulator'>
    <link name="link1">
      <pose frame=''>0 0 0 0 0 0</pose>
      <inertial>
        <pose frame='link1'>0.5 0 0 0 0 0</pose>
        <mass>1.0</mass>
        <inertia>
          <ixx>0.005</ixx>
          <ixy>0.</ixy>
          <ixz>0.0</ixz>
          <iyy>0.006</iyy>
          <izz>0.003</izz>
        </inertia>        
      </inertial>
      <collision name='link1_collision'>
        <pose frame=''>0.5 0 0 0 0 0</pose>        
        <geometry>
          <box>
            <size>1 0.15 0.15</size>
          </box>          
        </geometry>      
      </collision>  
      <visual name='link1_visual'>
        <pose frame=''>0.5 0 0 0 0 0</pose>      
        <geometry>
          <box>
            <size>1 0.15 0.15</size>
          </box>          
        </geometry>
        <material>          
          <ambient>1.0 0.5019607843137254902 0 1.0</ambient>
        </material>      
      </visual>
      <self_collide>0</self_collide>
    </link>
    
    <link name="link2">
      <pose frame=''>1 0 0 0 0 0</pose>
      <inertial>
        <pose frame='link2'>0.5 0 0 0 0 0</pose>
        <mass>1.0</mass>
        <inertia>
          <ixx>0.005</ixx>
          <ixy>0.</ixy>
          <ixz>0.0</ixz>
          <iyy>0.006</iyy>
          <izz>0.003</izz>
        </inertia>  
      </inertial>
      <collision name='link2_collision'>
        <pose frame=''>0.5 0 0 0 0 0</pose>        
        <geometry>
          <box>
            <size>1 0.15 0.15</size>
          </box>          
        </geometry>      
      </collision>  
      <visual name='link2_visual'>
        <pose frame=''>0.5 0 0 0 0 0</pose>      
        <geometry>
          <box>
            <size>1 0.15 0.15</size>
          </box>          
        </geometry>
        <material>          
          <ambient>1.0 0.5019607843137254902 0 1.0</ambient>
        </material>      
      </visual>
      <self_collide>0</self_collide>  
    </link>
    
    <link name="link3">
      <pose frame=''>2 0 0 0 0 0</pose>
      <inertial>
        <pose frame='link3'>0.5 0 0 0 0 0</pose>
        <mass>1.0</mass>
        <inertia>
          <ixx>0.005</ixx>
          <ixy>0.</ixy>
          <ixz>0.0</ixz>
          <iyy>0.006</iyy>
          <izz>0.003</izz>
        </inertia>  
      </inertial>
      <collision name='link3_collision'>
        <pose frame=''>0.5 0 0 0 0 0</pose>        
        <geometry>
          <box>
            <size>1 0.15 0.15</size>
          </box>          
        </geometry>      
      </collision>  
      <visual name='link3_visual'>
        <pose frame=''>0.5 0 0 0 0 0</pose>      
        <geometry>
          <box>
            <size>1 0.15 0.15</size>
          </box>          
        </geometry>
        <material>          
          <ambient>1.0 0.5019607843137254902 0 1.0</ambient>
        </material>      
      </visual>
      <self_collide>0</self_collide>  
    </link>
    
    <link name="link4">
      <pose frame=''>3 0 0 0 0 0</pose>
      <inertial>
        <pose frame='link4'>0.5 0 0 0 0 0</pose>
        <mass>1.0</mass>
        <inertia>
          <ixx>0.005</ixx>
          <ixy>0.</ixy>
          <ixz>0.0</ixz>
          <iyy>0.006</iyy>
          <izz>0.003</izz>
        </inertia>  
      </inertial>
      <collision name='link4_collision'>
        <pose frame=''>0.5 0 0 0 0 0</pose>        
        <geometry>
          <box>
            <size>1 0.15 0.15</size>
          </box>          
        </geometry>      
      </collision>  
      <visual name='link4_visual'>
        <pose frame=''>0.5 0 0 0 0 0</pose>      
        <geometry>
          <box>
            <size>1 0.15 0.15</size>
          </box>          
        </geometry>
        <material>          
          <ambient>1.0 0.5019607843137254902 0 1.0</ambient>
        </material>      
      </visual>      
      <self_collide>0</self_collide>  
    </link>
    
    <joint name="joint1" type="revolute">
      <parent>world</parent>
      <child>link1</child>
      <axis>
        <xyz>0 0 1</xyz>      
        <limit>
          <lower>-0.64159265358979323846</lower>
          <upper>2.64159265358979323846</upper>
          <velocity>6</velocity>
          <effort>50</effort>
        </limit>
        <dynamics>
          <damping>1.0</damping>
          <friction>0.2</friction>
        </dynamics>
        <use_parent_model_frame>1</use_parent_model_frame> 
      </axis>
      <physics>
        <ode>
          <implicit_spring_damper>1</implicit_spring_damper>
          <bounce>0</bounce>
          <limit>
            <erp>0.9</erp>
            <cfm>0</cfm>
          </limit>
        </ode>
      </physics>    
    </joint>
    
    <joint name="joint2" type="revolute">
      <parent>link1</parent>
      <child>link2</child>
      <axis>
        <xyz>0 1 0</xyz>      
        <limit>
          <lower>-1.74159265358979323846</lower>
          <upper>1.74159265358979323846</upper>
          <velocity>2</velocity>
          <effort>30</effort>
        </limit>
        <dynamics>
          <damping>1.0</damping>
          <friction>0.2</friction>
        </dynamics>
        <use_parent_model_frame>1</use_parent_model_frame> 
      </axis>
      <physics>
        <ode>
          <implicit_spring_damper>1</implicit_spring_damper>
          <bounce>0</bounce>
          <limit>
            <erp>0.9</erp>
            <cfm>0</cfm>
          </limit>
        </ode>
      </physics>    
    </joint>
    
    <joint name="joint3" type="revolute">
      <parent>link2</parent>
      <child>link3</child>
      <axis>
        <xyz>0 1 0</xyz>      
        <limit>
          <lower>-2.54159265358979323846</lower>          
          <upper>2.54159265358979323846</upper>
          <velocity>2</velocity>
          <effort>40</effort>
        </limit>
        <dynamics>
          <damping>1.0</damping>
          <friction>0.2</friction>
        </dynamics>
        <use_parent_model_frame>1</use_parent_model_frame> 
      </axis>
      <physics>
        <ode>
          <implicit_spring_damper>1</implicit_spring_damper>
          <bounce>0</bounce>
          <limit>
            <erp>0.9</erp>
            <cfm>0</cfm>
          </limit>
        </ode>
      </physics>
    </joint>
    
    <joint name="joint4" type="revolute">
      <parent>link3</parent>
      <child>link4</child>
      <axis>
        <xyz>0 0 1</xyz>      
        <limit>
          <lower>-1.94159265358979323846</lower>
          <upper>1.94159265358979323846</upper>
          <velocity>2</velocity>
          <effort>5</effort>
        </limit>
        <dynamics>
          <damping>1.0</damping>
          <friction>0.2</friction>
        </dynamics>
        <use_parent_model_frame>1</use_parent_model_frame> 
      </axis>
      <physics>
        <ode>
          <implicit_spring_damper>1</implicit_spring_damper>
          <bounce>0</bounce>
          <limit>
            <erp>0.9</erp>
            <cfm>0</cfm>
          </limit>
        </ode>
      </physics>    
    </joint>    
  </model>

</sdf>
